<?xml version="1.0"?>
<robot xmlns:xacro="http://www.ros.org/wiki/xacro" name="omni">
  
  <link name="base_link">
    <visual>
      <!--origin xyz="0.074832 0 -0.05929412" rpy="0 0 0" /-->
      <!--origin xyz="0.115067 0 -0.05929412" rpy="0 0 0" /-->
      <origin xyz="0.115067 0 0.00690588" rpy="0 0 0" />
      
      <geometry>
        <mesh filename="package://my_repository/meshes/STL/base_link.STL" />        
      </geometry>
      <material name="">
        <color rgba="1 0.96078 0.35686 1" />
      </material>
    </visual>
    <collision>
      <origin xyz="0.115067 0 0.00690588" rpy="0 0 0" />
      <geometry>
        <mesh filename="package://my_repository/meshes/STL/base_link.STL" />        
      </geometry>
    </collision>
  </link>
  <!--Insert the Xtion with its frames-->
  <!--xacro:xtion parent="base_link" x_loc="-0.253" y_loc="0" z_loc="0.29" rr="0" rp="0" ry="0"/-->
  <link name="ul_ranger">
  </link>

  <joint name="ulranger" type="fixed">

    <origin xyz="0.244064 0 0.0232" rpy="0 0 0" />  <!--z:=-0.058-->

    <parent link="base_link" />

    <child link="ul_ranger" />

  </joint>  
  <link name="imu">
  </link>

  <joint name="imu_link" type="fixed">

    <origin xyz="0.02 0.11 0.0132" rpy="0 0 0" />  <!--z:=-0.058-->

    <parent link="base_link" />

    <child link="imu" />

  </joint>  
  <link name="xtion_platform">
      <inertial>
        <mass value="0.01" />
        <origin xyz="0 0 0" />
        <inertia ixx="0.001" ixy="0.0" ixz="0.0"
                 iyy="0.001" iyz="0.0" izz="0.001" />
      </inertial>

      <visual>
        <origin xyz="0 0 0 " rpy="0 0 0" />
        <geometry>
          <box size="0.003 0.003 0.003"/>
        </geometry>
      </visual>
      <collision>
        <origin xyz="0.0 0.0 0.0" rpy="0 0 0" />
        <geometry>
          <box size="0.003 0.003 0.003"/>
        </geometry>
      </collision>
    </link>
    <joint name="base_xtion_platform_joint" type="fixed">
      <!--origin xyz="-0.2765 0.0292 0.268" rpy="0 0 0" /-->
      <origin xyz="-0.2765 0.0292 0.3342" rpy="0 0 0" />      
      <parent link="base_link" />
      <child link="xtion_platform" />
    </joint>    
    <link name="camera_linkvisual">
      <inertial>
        <mass value="0.01" />
        <origin xyz="0 0 0" />
        <inertia ixx="0.001" ixy="0.0" ixz="0.0"
                 iyy="0.001" iyz="0.0" izz="0.001" />
      </inertial>
      <visual>
        <origin xyz="-0.0255 -0.119794 -0.028" rpy="0 0 0" />
        <geometry>
          <mesh filename="package://my_repository/meshes/STL/AsusXtion.STL" />
        </geometry>
        <material name="">
          <color rgba="0 0 0.6 0.7" />
        </material>
      </visual>
      <collision>
        <origin xyz="-0.01 0.0 0.0" rpy="0 0 0" />
        <geometry>
          <box size="0.04 0.18 0.03"/>
        </geometry>
      </collision>
    </link>


    <link name="camera_link">
      <inertial>
        <mass value="0.01" />
        <origin xyz="0 0 0" />
        <inertia ixx="0.001" ixy="0.0" ixz="0.0"
                 iyy="0.001" iyz="0.0" izz="0.001" />
      </inertial>
    </link>
    <joint name="base_xtion_jointcamera" type="fixed">
      <!--origin xyz="-0.2715 0.0662 0.29" rpy="0 0 0" /-->
      <origin xyz="-0.2715 0.0662 0.3562" rpy="0 0 0" />
      <parent link="base_link" />
      <child link="camera_link" />
    </joint>
    <!-- platform for xtion -->

    

    <joint name="base_xtion_joint" type="fixed">
      <origin xyz="0.0074381 0 0.01875" rpy="0 0 0" />
      
      <parent link="xtion_platform" />
      <child link="camera_linkvisual" />
    </joint>
    <!--	TRANSFORMS FOR THE CAMERA-->
    <link name="xtion_link">
      <inertial>
        <mass value="0.01" />
        <origin xyz="0 0 0" />
        <inertia ixx="0.001" ixy="0.0" ixz="0.0"
                 iyy="0.001" iyz="0.0" izz="0.001" />
      </inertial>
      <visual>
        <origin xyz="0 0 0" rpy="0 0 0" />
        
        <material name="">
          <color rgba="1 0.96078 0.35686 1" />
        </material>
      </visual>
      <collision>
        <origin xyz="-0.01 0.0 0.0" rpy="0 0 0" />
        <geometry>
          <box size="0.04 0.18 0.03"/>
        </geometry>
      </collision>
    </link>

    <!-- platform for xtion -->

    

    <joint name="base_xtion_joint2" type="fixed">
      <origin xyz="0.0074381 0 0.01875" rpy="0 0 0" />
      <parent link="xtion_platform" />
      <child link="xtion_link" />
    </joint>
    <link name="camera_depth_frame">
      <inertial>
        <mass value="0.01" />
        <origin xyz="0 0 0" />
        <inertia ixx="0.001" ixy="0.0" ixz="0.0"
                 iyy="0.001" iyz="0.0" izz="0.001" />
      </inertial>
    </link>
    <joint name="xtion_depth_joint" type="fixed">
      <origin xyz="0 0.018 0" rpy="0 0 0" />
      <parent link="xtion_link" />
      <child link="camera_depth_frame" />
    </joint>

    
    <link name="camera_depth_optical_frame">
      <inertial>
        <mass value="0.001" />
        <origin xyz="0 0 0" />
        <inertia ixx="0.0001" ixy="0.0" ixz="0.0"
                 iyy="0.0001" iyz="0.0" izz="0.0001" />
      </inertial>
    </link>
    <joint name="xtion_depth_optical_joint" type="fixed">
      <origin xyz="0 0 0" rpy="0 0 0" />
      <parent link="camera_depth_frame" />
      <child link="camera_depth_optical_frame" />
    </joint>

    
    <link name="camera_rgb_frame">
      <inertial>
        <mass value="0.001" />
        <origin xyz="0 0 0" />
        <inertia ixx="0.0001" ixy="0.0" ixz="0.0"
                 iyy="0.0001" iyz="0.0" izz="0.0001" />
      </inertial>
    </link>
    <joint name="xtion_rgb_joint" type="fixed">
      <origin xyz="0 -0.005 0" rpy="0 0 0" />
      <parent link="xtion_link" />
      <child link="camera_rgb_frame" />
    </joint>

    
    <link name="camera_rgb_optical_frame">
      <inertial>
        <mass value="0.001" />
        <origin xyz="0 0 0" />
        <inertia ixx="0.0001" ixy="0.0" ixz="0.0"
                 iyy="0.0001" iyz="0.0" izz="0.0001" />
      </inertial>
    </link>
    <joint name="xtion_rgb_optical_joint" type="fixed">
      <origin xyz="0 0 0" rpy="0 0 0" />
      <parent link="camera_rgb_frame" />
      <child link="camera_rgb_optical_frame" />
    </joint>  


  <!--here ends transforms for the camera-->
  <link name="FR_wheel">
    <visual>
      <origin xyz="-0.022505 -0.02227 0.00205" rpy="0 0 0" />
      <geometry>
        <mesh filename="package://my_repository/meshes/STL/FR_wheel.STL" /> 
        <!--cylinder length="0.03" radius="0.05"/-->
      </geometry>
      <material name="">
        <color rgba="0.02 0.4 0 1" />
      </material>
    </visual>
    <collision>
      <origin xyz="-0.022505 -0.02227 0.00205" rpy="0 0 0" />
      <geometry>
        <mesh filename="package://my_repository/meshes/STL/FR_wheel.STL" /> 
        <!--cylinder length="0.03" radius="0.05"/-->
      </geometry>
    </collision>
  </link>
  <joint name="FR" type="continuous">
    <!--origin xyz="0.166545 -0.15401 -0.0162" rpy="0 0  0" /-->
    <origin xyz="0.166545 -0.15401 0.05" rpy="0 0  0" />
    <parent link="base_link" />
    <child link="FR_wheel" />
    <axis xyz="0 1 0" />
    <limit effort="0" velocity="0" />
  </joint>
  <link name="FL_wheel">
    <visual>
      <origin xyz="0.002 -0.03227 -0.0565" rpy="0 0 0" />
      <geometry>
        <mesh filename="package://my_repository/meshes/STL/FL_wheel.STL" />
      </geometry>
      <material name="">
        <color rgba="0.02 0.4 0 1" />
      </material>
    </visual>
    <collision>
      <origin xyz="0.002 -0.03227 -0.0565" rpy="0 0 0" />
      <geometry>
        <mesh filename="package://my_repository/meshes/STL/FL_wheel.STL" />
      </geometry>
    </collision>
  </link>
  <joint name="FL" type="continuous">
    <origin xyz="0.166545 0.15401 0.05" rpy="0 0  0" />
    <parent link="base_link" />
    <child link="FL_wheel" />
    <axis xyz="0 1 0" />
    <limit effort="0" velocity="0" />
  </joint>
  <link name="RR_wheel">
    <visual>
      <origin xyz="0.002 -0.03227 -0.0565" rpy="0 0 0" />
      <geometry>
        <mesh filename="package://my_repository/meshes/STL/RR_wheel.STL" />
      </geometry>
      <material name="">
        <color rgba="0.02 0.4 0 1" />
      </material>
    </visual>
    <collision>
      <origin xyz="0.002 -0.03227 -0.0565" rpy="0 0 0" />
      <geometry>
        <mesh filename="package://my_repository/meshes/STL/RR_wheel.STL" />
      </geometry>
    </collision>
  </link>
  <joint name="RR" type="continuous">
    <origin xyz="-0.166545 -0.15401 0.05" rpy="0 0 0" />
    <parent link="base_link" />
    <child link="RR_wheel" />
    <axis xyz="0 1 0" />
    <limit effort="0" velocity="0" />
  </joint>
  <link name="RL_wheel">
    <visual>
      <origin xyz="-0.022505 -0.02227 0.00205" rpy="0 0 0" />
      <geometry>
        <mesh filename="package://my_repository/meshes/STL/RL_wheel.STL" />
      </geometry>
      <material name="">
        <color rgba="0.02 0.4 0 1" />
      </material>
    </visual>
    <collision>
      <origin xyz="-0.022505 -0.02227 0.00205" rpy="0 0 0" />
      <geometry>
        <mesh filename="package://my_repository/meshes/STL/RL_wheel.STL" />
      </geometry>
    </collision>
  </link>
  <joint name="RL" type="continuous">
    <origin xyz="-0.166545 0.15401 0.05" rpy="0 0 0" />
    <parent link="base_link" />
    <child link="RL_wheel" />
    <axis xyz="0 1 0" />
    <limit effort="0" velocity="0" />
  </joint>
  <link name="shovel_link"/>
  <joint name="Shovel" type="fixed">
    <!--origin xyz="0.284064 0 -0.058" rpy="0 0 0" /-->
    <origin xyz="0.284064 0 0.0082" rpy="0 0 0" />
    <parent link="base_link" />
    <child link="shovel_link" />
    <axis xyz="0 0 0" />
  </joint>
</robot>
