<?xml version="1.0"?>
<robot xmlns:xacro="http://www.ros.org/wiki/xacro" name="omni">
  <xacro:include filename="$(find my_repository)/robots/xtion.urdf.xacro" /> 
  <link name="base_link">
    <visual>
      <!--origin xyz="0.074832 0 -0.05929412" rpy="0 0 0" /-->
      <origin xyz="0.115067 0 -0.05929412" rpy="0 0 0" />
      <geometry>
        <mesh filename="package://my_repository/meshes/STL/base_link.STL" />        
      </geometry>
      <material name="">
        <color rgba="1 0.96078 0.35686 1" />
      </material>
    </visual>
    <collision>
      <origin xyz="0.115067 0 -0.05929412" rpy="0 0 0" />
      <geometry>
        <mesh filename="package://my_repository/meshes/STL/base_link.STL" />        
      </geometry>
    </collision>
  </link>
  <!--Insert the Xtion with its frames-->
  <xtion parent="plate_xtension_link" rp="0" rr="0" ry="0" x_loc="-0.253" y_loc="0" z_loc="0.29"/>
<!--  
<link name="camera_depth_frame">
    <visual>
      <origin xyz="-0.040235 -0.090594 -0.03047" rpy="0 0 0" />
      <geometry>
        <mesh filename="package://my_repository/meshes/STL/AsusXtion.STL" />
        </geometry>
      <material name="">
        <color rgba="0 0 0 1" />
      </material>
    </visual>
  </link>
  <joint name="camera" type="fixed">
    <origin xyz="-0.253 0.0 0.29" rpy="0 0 0" />
    <parent link="base_link" />
    <child link="camera_depth_frame" />
    <axis xyz="0 0 0" />
  </joint>
-->
  <link name="FR_wheel">
    <visual>
      <origin xyz="-0.022505 -0.02227 0.00205" rpy="0 0 0" />
      <geometry>
        <mesh filename="package://my_repository/meshes/STL/FR_wheel.STL" /> 
        <!--cylinder length="0.03" radius="0.05"/-->
      </geometry>
      <material name="">
        <color rgba="0.05882 0.69019 0.03921 1" />
      </material>
    </visual>
    <collision>
      <origin xyz="-0.022505 -0.02227 0.00205" rpy="0 0 0" />
      <geometry>
        <mesh filename="package://my_repository/meshes/STL/FR_wheel.STL" /> 
        <!--cylinder length="0.03" radius="0.05"/-->
      </geometry>
    </collision>
  </link>
  <joint name="FR" type="continuous">
    <origin xyz="0.166545 -0.15401 -0.0162" rpy="0 0  0" />
    <parent link="base_link" />
    <child link="FR_wheel" />
    <axis xyz="0 1 0" />
    <limit effort="0" velocity="0" />
  </joint>
  <link name="FL_wheel">
    <visual>
      <origin xyz="0.002 -0.03227 -0.0565" rpy="0 0 0" />
      <geometry>
        <mesh filename="package://my_repository/meshes/STL/FL_wheel.STL" />
      </geometry>
      <material name="">
        <color rgba="0.05882 0.69019 0.03921 1" />
      </material>
    </visual>
    <collision>
      <origin xyz="0.002 -0.03227 -0.0565" rpy="0 0 0" />
      <geometry>
        <mesh filename="package://my_repository/meshes/STL/FL_wheel.STL" />
      </geometry>
    </collision>
  </link>
  <joint name="FL" type="continuous">
    <origin xyz="0.166545 0.15401 -0.0162" rpy="0 0  0" />
    <parent link="base_link" />
    <child link="FL_wheel" />
    <axis xyz="0 1 0" />
    <limit effort="0" velocity="0" />
  </joint>
  <link name="RR_wheel">
    <visual>
      <origin xyz="0.002 -0.03227 -0.0565" rpy="0 0 0" />
      <geometry>
        <mesh filename="package://my_repository/meshes/STL/RR_wheel.STL" />
      </geometry>
      <material name="">
        <color rgba="0.05882 0.69019 0.03921 1" />
      </material>
    </visual>
    <collision>
      <origin xyz="0.002 -0.03227 -0.0565" rpy="0 0 0" />
      <geometry>
        <mesh filename="package://my_repository/meshes/STL/RR_wheel.STL" />
      </geometry>
    </collision>
  </link>
  <joint name="RR" type="continuous">
    <origin xyz="-0.166545 -0.15401 -0.0162" rpy="0 0 0" />
    <parent link="base_link" />
    <child link="RR_wheel" />
    <axis xyz="0 1 0" />
    <limit effort="0" velocity="0" />
  </joint>
  <link name="RL_wheel">
    <visual>
      <origin xyz="-0.022505 -0.02227 0.00205" rpy="0 0 0" />
      <geometry>
        <mesh filename="package://my_repository/meshes/STL/RL_wheel.STL" />
      </geometry>
      <material name="">
        <color rgba="0.05882 0.69019 0.03921 1" />
      </material>
    </visual>
    <collision>
      <origin xyz="-0.022505 -0.02227 0.00205" rpy="0 0 0" />
      <geometry>
        <mesh filename="package://my_repository/meshes/STL/RL_wheel.STL" />
      </geometry>
    </collision>
  </link>
  <joint name="RL" type="continuous">
    <origin xyz="-0.166545 0.15401 -0.0162" rpy="0 0 0" />
    <parent link="base_link" />
    <child link="RL_wheel" />
    <axis xyz="0 1 0" />
    <limit effort="0" velocity="0" />
  </joint>
  <link name="shovel_link"/>
  <joint name="Shovel" type="fixed">
    <origin xyz="0.3 0 -0.04" rpy="0 0 0" />
    <parent link="base_link" />
    <child link="shovel_link" />
    <axis xyz="0 0 0" />
  </joint>
</robot>
